2022-02-11 07:27:55,378 ERROR: Exception on /explore [GET] [in /home/jake/ShotStar/venv/lib/python3.8/site-packages/flask/app.py:1457]
Traceback (most recent call last):
  File "/home/jake/ShotStar/venv/lib/python3.8/site-packages/flask/app.py", line 2073, in wsgi_app
    response = self.full_dispatch_request()
  File "/home/jake/ShotStar/venv/lib/python3.8/site-packages/flask/app.py", line 1518, in full_dispatch_request
    rv = self.handle_user_exception(e)
  File "/home/jake/ShotStar/venv/lib/python3.8/site-packages/flask/app.py", line 1516, in full_dispatch_request
    rv = self.dispatch_request()
  File "/home/jake/ShotStar/venv/lib/python3.8/site-packages/flask/app.py", line 1502, in dispatch_request
    return self.ensure_sync(self.view_functions[rule.endpoint])(**req.view_args)
  File "/home/jake/ShotStar/venv/lib/python3.8/site-packages/flask_login/utils.py", line 272, in decorated_view
    return func(*args, **kwargs)
  File "/home/jake/ShotStar/app/main/routes.py", line 42, in explore
    games = Game.query.order_by(Game.timestamp.desc()).paginate(page, current_app.config['GAMES_PER_PAGE'], False)
  File "/home/jake/ShotStar/venv/lib/python3.8/site-packages/flask_sqlalchemy/__init__.py", line 534, in paginate
    items = self.limit(per_page).offset((page - 1) * per_page).all()
  File "/home/jake/ShotStar/venv/lib/python3.8/site-packages/sqlalchemy/orm/query.py", line 2759, in all
    return self._iter().all()
  File "/home/jake/ShotStar/venv/lib/python3.8/site-packages/sqlalchemy/engine/result.py", line 1361, in all
    return self._allrows()
  File "/home/jake/ShotStar/venv/lib/python3.8/site-packages/sqlalchemy/engine/result.py", line 400, in _allrows
    rows = self._fetchall_impl()
  File "/home/jake/ShotStar/venv/lib/python3.8/site-packages/sqlalchemy/engine/result.py", line 1274, in _fetchall_impl
    return self._real_result._fetchall_impl()
  File "/home/jake/ShotStar/venv/lib/python3.8/site-packages/sqlalchemy/engine/result.py", line 1686, in _fetchall_impl
    return list(self.iterator)
  File "/home/jake/ShotStar/venv/lib/python3.8/site-packages/sqlalchemy/orm/loading.py", line 147, in chunks
    fetch = cursor._raw_all_rows()
  File "/home/jake/ShotStar/venv/lib/python3.8/site-packages/sqlalchemy/engine/result.py", line 392, in _raw_all_rows
    return [make_row(row) for row in rows]
  File "/home/jake/ShotStar/venv/lib/python3.8/site-packages/sqlalchemy/engine/result.py", line 392, in <listcomp>
    return [make_row(row) for row in rows]
ValueError: Couldn't parse datetime string: '2022-01-01'
2022-02-11 07:30:35,237 INFO: ShotStar startup [in /home/jake/ShotStar/app/__init__.py:71]
2022-02-11 07:30:39,183 ERROR: Exception on /explore [GET] [in /home/jake/ShotStar/venv/lib/python3.8/site-packages/flask/app.py:1457]
Traceback (most recent call last):
  File "/home/jake/ShotStar/venv/lib/python3.8/site-packages/flask/app.py", line 2073, in wsgi_app
    response = self.full_dispatch_request()
  File "/home/jake/ShotStar/venv/lib/python3.8/site-packages/flask/app.py", line 1518, in full_dispatch_request
    rv = self.handle_user_exception(e)
  File "/home/jake/ShotStar/venv/lib/python3.8/site-packages/flask/app.py", line 1516, in full_dispatch_request
    rv = self.dispatch_request()
  File "/home/jake/ShotStar/venv/lib/python3.8/site-packages/flask/app.py", line 1502, in dispatch_request
    return self.ensure_sync(self.view_functions[rule.endpoint])(**req.view_args)
  File "/home/jake/ShotStar/venv/lib/python3.8/site-packages/flask_login/utils.py", line 272, in decorated_view
    return func(*args, **kwargs)
  File "/home/jake/ShotStar/app/main/routes.py", line 42, in explore
    games = Game.query.order_by(Game.timestamp.desc()).paginate(page, current_app.config['GAMES_PER_PAGE'], False)
  File "/home/jake/ShotStar/venv/lib/python3.8/site-packages/flask_sqlalchemy/__init__.py", line 534, in paginate
    items = self.limit(per_page).offset((page - 1) * per_page).all()
  File "/home/jake/ShotStar/venv/lib/python3.8/site-packages/sqlalchemy/orm/query.py", line 2759, in all
    return self._iter().all()
  File "/home/jake/ShotStar/venv/lib/python3.8/site-packages/sqlalchemy/engine/result.py", line 1361, in all
    return self._allrows()
  File "/home/jake/ShotStar/venv/lib/python3.8/site-packages/sqlalchemy/engine/result.py", line 400, in _allrows
    rows = self._fetchall_impl()
  File "/home/jake/ShotStar/venv/lib/python3.8/site-packages/sqlalchemy/engine/result.py", line 1274, in _fetchall_impl
    return self._real_result._fetchall_impl()
  File "/home/jake/ShotStar/venv/lib/python3.8/site-packages/sqlalchemy/engine/result.py", line 1686, in _fetchall_impl
    return list(self.iterator)
  File "/home/jake/ShotStar/venv/lib/python3.8/site-packages/sqlalchemy/orm/loading.py", line 147, in chunks
    fetch = cursor._raw_all_rows()
  File "/home/jake/ShotStar/venv/lib/python3.8/site-packages/sqlalchemy/engine/result.py", line 392, in _raw_all_rows
    return [make_row(row) for row in rows]
  File "/home/jake/ShotStar/venv/lib/python3.8/site-packages/sqlalchemy/engine/result.py", line 392, in <listcomp>
    return [make_row(row) for row in rows]
ValueError: Couldn't parse datetime string: '2022-01-01'
2022-02-11 07:30:41,209 ERROR: Exception on /index [GET] [in /home/jake/ShotStar/venv/lib/python3.8/site-packages/flask/app.py:1457]
Traceback (most recent call last):
  File "/home/jake/ShotStar/venv/lib/python3.8/site-packages/flask/app.py", line 2073, in wsgi_app
    response = self.full_dispatch_request()
  File "/home/jake/ShotStar/venv/lib/python3.8/site-packages/flask/app.py", line 1518, in full_dispatch_request
    rv = self.handle_user_exception(e)
  File "/home/jake/ShotStar/venv/lib/python3.8/site-packages/flask/app.py", line 1516, in full_dispatch_request
    rv = self.dispatch_request()
  File "/home/jake/ShotStar/venv/lib/python3.8/site-packages/flask/app.py", line 1502, in dispatch_request
    return self.ensure_sync(self.view_functions[rule.endpoint])(**req.view_args)
  File "/home/jake/ShotStar/venv/lib/python3.8/site-packages/flask_login/utils.py", line 272, in decorated_view
    return func(*args, **kwargs)
  File "/home/jake/ShotStar/app/main/routes.py", line 33, in index
    return render_template('index.html', title='Home', form=form,
  File "/home/jake/ShotStar/venv/lib/python3.8/site-packages/flask/templating.py", line 148, in render_template
    ctx.app.jinja_env.get_or_select_template(template_name_or_list),
  File "/home/jake/ShotStar/venv/lib/python3.8/site-packages/jinja2/environment.py", line 1068, in get_or_select_template
    return self.get_template(template_name_or_list, parent, globals)
  File "/home/jake/ShotStar/venv/lib/python3.8/site-packages/jinja2/environment.py", line 997, in get_template
    return self._load_template(name, globals)
  File "/home/jake/ShotStar/venv/lib/python3.8/site-packages/jinja2/environment.py", line 958, in _load_template
    template = self.loader.load(self, name, self.make_globals(globals))
  File "/home/jake/ShotStar/venv/lib/python3.8/site-packages/jinja2/loaders.py", line 137, in load
    code = environment.compile(source, name, filename)
  File "/home/jake/ShotStar/venv/lib/python3.8/site-packages/jinja2/environment.py", line 757, in compile
    self.handle_exception(source=source_hint)
  File "/home/jake/ShotStar/venv/lib/python3.8/site-packages/jinja2/environment.py", line 925, in handle_exception
    raise rewrite_traceback_stack(source=source)
  File "/home/jake/ShotStar/app/templates/index.html", line 32, in template
    {% block app_content %}
jinja2.exceptions.TemplateAssertionError: block 'app_content' defined twice
2022-02-11 07:31:27,923 INFO: ShotStar startup [in /home/jake/ShotStar/app/__init__.py:71]
